<robot name="6axis_robot">

	<!-- * * * Link Definitions * * * -->

  	<link name="upper_base_link">
		<visual>
			<origin xyz="0 0 0" rpy="0 0 0"/>  <!-- 0 0 0.025 -->
			<geometry>
				<cylinder radius="0.25" length="0.05"/>
			</geometry>
	     	<material name="Cyan3">
				<color rgba="0 0.5 0.5 0"/>
			</material>
	   </visual>
	</link>

  	<link name="torso_link">
		<visual>
			<origin xyz="0 0 0.05" rpy="0 0 0"/>
			<geometry>
				<cylinder radius="0.2" length="0.15"/>
			</geometry>
	     	<material name="Grey2">
				<color rgba="0.9 0.9 0.9 1.0"/>
			</material>
	   </visual>
	</link>
	
	<link name="left_shoulder_link">
		<visual>
			<origin xyz="0 0 0" rpy="0 0 0"/>
			<geometry>
				<box size="0.05 0.05 0.1"/>
			</geometry>
	     	<material name="Green1">
				<color rgba="0 1 0 1.0"/>
			</material>
	   </visual>
	</link>
	
	<link name="left_shoulder_forward_link">
		<visual>
			<origin xyz="0 0 0" rpy="0 0 0"/>
			<geometry>
				<box size="0.12 0.12 0.45"/>
			</geometry>
	     	<material name="Blue1">
				<color rgba="0 0 0.8 1.0"/>
			</material>
	   </visual>
	</link>

	<link name="left_shoulder_up_link">
		<visual>
			<origin xyz="0 0 0" rpy="0 0 0"/>
			<geometry>
				<box size="0.1 0.1 0.25"/>
			</geometry>
	     	<material name="Purple1">
				<color rgba="0.5 0 0.5 0.5 1.0"/>
			</material>
	   </visual>
	</link>
	
	<link name="left_upper_arm_link">
		<visual>
			<origin xyz="0 0 0" rpy="0 0 0"/>
			<geometry>
				<cylinder radius="0.05" length="0.2"/>
			</geometry>
	     	<material name="Grey1">
				<color rgba="0.9 0.9 0.9 1.0"/>
			</material>
	   </visual>
	</link>
	
	<link name="left_elbow_link">
		<visual>
			<origin xyz="0 0 0" rpy="0 0 0"/>
			<geometry>
				<box size="0.07 0.07 0.25"/>
			</geometry>
	     	<material name="Red2">
				<color rgba="0.5 0 0 1.0"/>
			</material>
	   </visual>
	</link>
	
	<link name="left_wrist_link">
		<visual>
			<origin xyz="0 0 0" rpy="0 0 0"/>
			<geometry>
				<box size="0.05 0.05 0.18"/>
			</geometry>
	     	<material name="Green2">
				<color rgba="0 0.7 0 1.0"/>
			</material>
	   </visual>
	</link>
	
	<link name="left_hand_link">
		<visual>
			<origin xyz="0 0 0" rpy="0 0 0"/>
			<geometry>
				<cylinder radius="0.025" length="0.1"/>
			</geometry>
	     	<material name="Grey">
				<color rgba="0.9 0.9 0.9 1.0"/>
			</material>
	   </visual>
	</link>
    
	
	<!-- * * * Joint Definitions * * * -->

	<joint name="torso_joint" type="revolute">
    	<parent link="upper_base_link"/>
    	<child link="torso_link"/>
    	<origin xyz="0 0 0.05" rpy="0 0 0"/>
    	<axis xyz="0 0 1"/>
    	<limit lower="-2.88" upper="2.88" effort="10" velocity="3"/>
  	</joint>
	
 	<joint name="left_shoulder_joint" type="fixed">
    	<parent link="torso_link"/>
    	<child link="left_shoulder_link"/>
    	<origin xyz="0 0 0.1" rpy="0 0 0"/>
	</joint>
	
 	<joint name="left_shoulder_forward_joint" type="revolute">
    	<parent link="left_shoulder_link"/>
    	<child link="left_shoulder_forward_link"/>
    	<origin xyz="0 0 0.1" rpy="0 0 0"/>
       	<limit lower="-2.81" upper="1.48" effort="10" velocity="3"/>
        <axis xyz="0 1 0"/>
	</joint>
	
 	<joint name="left_shoulder_up_joint" type="revolute">
    	<parent link="left_shoulder_forward_link"/>
    	<child link="left_shoulder_up_link"/>
    	<origin xyz="0 0 0.25" rpy="0 1.57 0"/>
       	<limit lower="-0.96" upper="3.23" effort="10" velocity="3"/>
        <axis xyz="0 1 0"/>
	</joint>
	
 	<joint name="left_upper_arm_joint" type="fixed">
    	<parent link="left_shoulder_up_link"/>
    	<child link="left_upper_arm_link"/>
    	<origin xyz="0 0 0.1" rpy="0 0 0"/>
	</joint>
	
 	<joint name="left_elbow_joint" type="revolute">
    	<parent link="left_upper_arm_link"/>
    	<child link="left_elbow_link"/>
    	<origin xyz="0 0 0.1" rpy="0 0 0"/>
       	<limit lower="-2.01" upper="2.01" effort="10" velocity="3"/>
        <axis xyz="0 0 1"/>
	</joint>

 	<joint name="left_wrist_joint" type="revolute">
    	<parent link="left_elbow_link"/>
    	<child link="left_wrist_link"/>
    	<origin xyz="0 0 0.12" rpy="0 0 0"/>
       	<limit lower="-2.01" upper="2.01" effort="10" velocity="3"/>
        <axis xyz="0 1 0"/>
	</joint>
	
 	<joint name="left_hand_joint" type="revolute">
    	<parent link="left_wrist_link"/>
    	<child link="left_hand_link"/>
    	<origin xyz="0 0 0.1" rpy="0 0 0"/>
        <limit lower="-6.28" upper="6.28" effort="10" velocity="3"/>
        <axis xyz="0 0 1"/>
	</joint>
 
</robot>